Workbook

Sheet Channel_Listings
A1: Marketplace | B1: Category | C1: Channel_SKU | D1: Pack_SKU | E1: Listing_Status | F1: ASIN_FSN_ID | G1: Listing_URL | H1: Last_Updated | I1: Comment
A2: Amazon | B2: {=IF(D2="","", INDEX(Product_Master!A:A, MATCH( INDEX(Pack_Master!B:B, MATCH(D2, Pack_Master!A:A, 0)), Product_Master!B:B, 0 ) ))} -> Apparel_ArmSleeves | C2: 14-32DR-R138 | D2: ARMSLEEVES-HALF-BLACK | E2: LIVE
A3: Amazon | B3: {=IF(D3="","", INDEX(Product_Master!A:A, MATCH( INDEX(Pack_Master!B:B, MATCH(D3, Pack_Master!A:A, 0)), Product_Master!B:B, 0 ) ))} -> Automotive_FaceMasks | C3: 2L-4L4E-SECU | D3: BANDANA-PATTERN-MULTICOLOR-PK10 | E3: LIVE
A4: Amazon | B4: {=IF(D4="","", INDEX(Product_Master!A:A, MATCH( INDEX(Pack_Master!B:B, MATCH(D4, Pack_Master!A:A, 0)), Product_Master!B:B, 0 ) ))} -> Apparel_Caps_Beanies | C4: 2W-LKH7-FA8Z | D4: CAP-BASEBALL-PLAIN-WHITE | E4: LIVE
A5: Amazon | B5: {=IF(D5="","", INDEX(Product_Master!A:A, MATCH( INDEX(Pack_Master!B:B, MATCH(D5, Pack_Master!A:A, 0)), Product_Master!B:B, 0 ) ))} -> Automotive_FaceMasks | C5: 48-J9LB-ACWM | D5: MASK-HALF-BLUE-PK1 | E5: LIVE
A6: Amazon | B6: {=IF(D6="","", INDEX(Product_Master!A:A, MATCH( INDEX(Pack_Master!B:B, MATCH(D6, Pack_Master!A:A, 0)), Product_Master!B:B, 0 ) ))} -> Apparel_Caps_Beanies | C6: 59-10E8-ZXMS | D6: CAP-GOLF-CHARCOAL | E6: LIVE
A7: Amazon | B7: {=IF(D7="","", INDEX(Product_Master!A:A, MATCH( INDEX(Pack_Master!B:B, MATCH(D7, Pack_Master!A:A, 0)), Product_Master!B:B, 0 ) ))} -> Automotive_FaceMasks | C7: 8D-6GQZ-DKR2 | D7: BANDANA-PATTERN-MULTICOLOR-PK5 | E7: LIVE
A8: Amazon | B8: {=IF(D8="","", INDEX(Product_Master!A:A, MATCH( INDEX(Pack_Master!B:B, MATCH(D8, Pack_Master!A:A, 0)), Product_Master!B:B, 0 ) ))} -> Apparel_ArmSleeves | C8: 96-7KTF-QMRW | D8: ARMSLEEVES-HALF-BLACK | E8: LIVE
A9: Amazon | B9: {=IF(D9="","", INDEX(Product_Master!A:A, MATCH( INDEX(Pack_Master!B:B, MATCH(D9, Pack_Master!A:A, 0)), Product_Master!B:B, 0 ) ))} -> Apparel_Tshirts | C9: A-TSHIRT-BLACK-PRINT-AMPM-L | D9: TSHIRT-BLACK-L | E9: LIVE | F9: B0DH3D29MC
A10: Amazon | B10: {=IF(D10="","", INDEX(Product_Master!A:A, MATCH( INDEX(Pack_Master!B:B, MATCH(D10, Pack_Master!A:A, 0)), Product_Master!B:B, 0 ) ))} -> Apparel_Tshirts | C10: A-TSHIRT-BLACK-PRINT-AMPM-M | D10: TSHIRT-BLACK-M | E10: LIVE | F10: B0DH3F2MKH
A11: Amazon | B11: {=IF(D11="","", INDEX(Product_Master!A:A, MATCH( INDEX(Pack_Master!B:B, MATCH(D11, Pack_Master!A:A, 0)), Product_Master!B:B, 0 ) ))} -> Apparel_Tshirts | C11: A-TSHIRT-BLACK-PRINT-AMPM-XL | D11: TSHIRT-BLACK-XL | E11: LIVE | F11: B0DH3DKJPF
A12: Amazon | B12: {=IF(D12="","", INDEX(Product_Master!A:A, MATCH( INDEX(Pack_Master!B:B, MATCH(D12, Pack_Master!A:A, 0)), Product_Master!B:B, 0 ) ))} -> Apparel_Tshirts | C12: A-TSHIRT-BLACK-PRINT-AMPM-XXL | D12: TSHIRT-BLACK-XXL | E12: LIVE | F12: B0DH3CL2GX
A13: Amazon | B13: {=IF(D13="","", INDEX(Product_Master!A:A, MATCH( INDEX(Pack_Master!B:B, MATCH(D13, Pack_Master!A:A, 0)), Product_Master!B:B, 0 ) ))} -> Apparel_Tshirts | C13: A-TSHIRT-BLACK-PRINT-ARTISLIFE-L | D13: TSHIRT-BLACK-L | E13: LIVE | F13: B0DH3D1GBY
A14: Amazon | B14: {=IF(D14="","", INDEX(Product_Master!A:A, MATCH( INDEX(Pack_Master!B:B, MATCH(D14, Pack_Master!A:A, 0)), Product_Master!B:B, 0 ) ))} -> Apparel_Tshirts | C14: A-TSHIRT-BLACK-PRINT-ARTISLIFE-M | D14: TSHIRT-BLACK-M | E14: LIVE | F14: B0DH3DHTX8
A15: Amazon | B15: {=IF(D15="","", INDEX(Product_Master!A:A, MATCH( INDEX(Pack_Master!B:B, MATCH(D15, Pack_Master!A:A, 0)), Product_Master!B:B, 0 ) ))} -> Apparel_Tshirts | C15: A-TSHIRT-BLACK-PRINT-ARTISLIFE-XL | D15: TSHIRT-BLACK-XL | E15: LIVE | F15: B0DH3F9Y8R
A16: Amazon | B16: {=IF(D16="","", INDEX(Product_Master!A:A, MATCH( INDEX(Pack_Master!B:B, MATCH(D16, Pack_Master!A:A, 0)), Product_Master!B:B, 0 ) ))} -> Apparel_Tshirts | C16: A-TSHIRT-BLACK-PRINT-ARTISLIFE-XXL | D16: TSHIRT-BLACK-XXL | E16: LIVE | F16: B0DH3CVPR8
A17: Amazon | B17: {=IF(D17="","", INDEX(Product_Master!A:A, MATCH( INDEX(Pack_Master!B:B, MATCH(D17, Pack_Master!A:A, 0)), Product_Master!B:B, 0 ) ))} -> Apparel_Tshirts | C17: A-TSHIRT-BLACK-PRINT-BETHEUNIQUEONE-L | D17: TSHIRT-BLACK-L | E17: LIVE | F17: B0DH3DKDT2
A18: Amazon | B18: {=IF(D18="","", INDEX(Product_Master!A:A, MATCH( INDEX(Pack_Master!B:B, MATCH(D18, Pack_Master!A:A, 0)), Product_Master!B:B, 0 ) ))} -> Apparel_Tshirts | C18: A-TSHIRT-BLACK-PRINT-BETHEUNIQUEONE-M | D18: TSHIRT-BLACK-M | E18: LIVE | F18: B0DH3DHLVL
A19: Amazon | B19: {=IF(D19="","", INDEX(Product_Master!A:A, MATCH( INDEX(Pack_Master!B:B, MATCH(D19, Pack_Master!A:A, 0)), Product_Master!B:B, 0 ) ))} -> Apparel_Tshirts | C19: A-TSHIRT-BLACK-PRINT-BETHEUNIQUEONE-XL | D19: TSHIRT-BLACK-XL | E19: LIVE | F19: B0DH3FGBRD
A20: Amazon | B20: {=IF(D20="","", INDEX(Product_Master!A:A, MATCH( INDEX(Pack_Master!B:B, MATCH(D20, Pack_Master!A:A, 0)), Product_Master!B:B, 0 ) ))} -> Apparel_Tshirts | C20: A-TSHIRT-BLACK-PRINT-BETHEUNIQUEONE-XXL | D20: TSHIRT-BLACK-XXL | E20: LIVE | F20: B0DH3FJBS8
... A60: Amazon | B60: {=IF(D60="","", INDEX(Product_Master!A:A, MATCH( INDEX(Pack_Master!B:B, MATCH(D60, Pack_Master!A:A, 0)), Product_Master!B:B, 0 ) ))} -> Apparel_Tshirts | C60: A-TSHIRT-BLACK-PRINT-THEMOON-XXL | D60: TSHIRT-BLACK-XXL | E60: LIVE | F60: B0DH3DL9JD
A61: Amazon | B61: {=IF(D61="","", INDEX(Product_Master!A:A, MATCH( INDEX(Pack_Master!B:B, MATCH(D61, Pack_Master!A:A, 0)), Product_Master!B:B, 0 ) ))} -> Apparel_ArmSleeves | C61: AG-MFT8-S8CP | D61: ARMSLEEVES-HALF-WHITE | E61: LIVE
A62: Amazon | B62: {=IF(D62="","", INDEX(Product_Master!A:A, MATCH( INDEX(Pack_Master!B:B, MATCH(D62, Pack_Master!A:A, 0)), Product_Master!B:B, 0 ) ))} -> Apparel_Accessories_Winter | C62: AJ-BMGV-XM6S | D62: MUFFLER-STRIPE-GREY | E62: LIVE
A63: Amazon | B63: {=IF(D63="","", INDEX(Product_Master!A:A, MATCH( INDEX(Pack_Master!B:B, MATCH(D63, Pack_Master!A:A, 0)), Product_Master!B:B, 0 ) ))} -> Apparel_Caps_Beanies | C63: AK-O5V0-6K6W | D63: CAP-BASEBALL-PLAIN-RED | E63: LIVE
A64: Amazon | B64: {=IF(D64="","", INDEX(Product_Master!A:A, MATCH( INDEX(Pack_Master!B:B, MATCH(D64, Pack_Master!A:A, 0)), Product_Master!B:B, 0 ) ))} -> Automotive_FaceMasks | C64: AK-ZZR6-ZP97 | D64: MASK-HALF-BLUE-PK1 | E64: LIVE
A65: Amazon | B65: {=IF(D65="","", INDEX(Product_Master!A:A, MATCH( INDEX(Pack_Master!B:B, MATCH(D65, Pack_Master!A:A, 0)), Product_Master!B:B, 0 ) ))} -> Apparel_ArmSleeves | C65: Arm-Full-Black | D65: ARMSLEEVES-FULL-BLACK | E65: LIVE
A66: Amazon | B66: {=IF(D66="","", INDEX(Product_Master!A:A, MATCH( INDEX(Pack_Master!B:B, MATCH(D66, Pack_Master!A:A, 0)), Product_Master!B:B, 0 ) ))} -> Apparel_Accessories_Winter | C66: BANDANA-HANKY-PAISLEY-BLACK | D66: BANDANA-HANKY-PAISLEY-BLACK | E66: LIVE | F66: B09DXJNDMW
A67: Amazon | B67: {=IF(D67="","", INDEX(Product_Master!A:A, MATCH( INDEX(Pack_Master!B:B, MATCH(D67, Pack_Master!A:A, 0)), Product_Master!B:B, 0 ) ))} -> Apparel_Accessories_Winter | C67: BANDANA-HANKY-PAISLEY-GREEN | D67: BANDANA-HANKY-PAISLEY-GREEN | E67: LIVE | F67: B0BNNHMQLR
A68: Amazon | B68: {=IF(D68="","", INDEX(Product_Master!A:A, MATCH( INDEX(Pack_Master!B:B, MATCH(D68, Pack_Master!A:A, 0)), Product_Master!B:B, 0 ) ))} -> Apparel_Accessories_Winter | C68: BANDANA-HANKY-PAISLEY-MAROON | D68: BANDANA-HANKY-PAISLEY-MAROON | E68: LIVE | F68: B09FJDN4TS
A69: Amazon | B69: {=IF(D69="","", INDEX(Product_Master!A:A, MATCH( INDEX(Pack_Master!B:B, MATCH(D69, Pack_Master!A:A, 0)), Product_Master!B:B, 0 ) ))} -> Apparel_Accessories_Winter | C69: BANDANA-HANKY-PAISLEY-NAVYBLUE | D69: BANDANA-HANKY-PAISLEY-NAVYBLUE | E69: LIVE | F69: B09DXHWHGF
A70: Amazon | B70: {=IF(D70="","", INDEX(Product_Master!A:A, MATCH( INDEX(Pack_Master!B:B, MATCH(D70, Pack_Master!A:A, 0)), Product_Master!B:B, 0 ) ))} -> Apparel_Accessories_Winter | C70: BANDANA-HANKY-PAISLEY-ORANGE | D70: BANDANA-HANKY-PAISLEY-ORANGE | E70: LIVE | F70: B09FJDBMYQ
A71: Amazon | B71: {=IF(D71="","", INDEX(Product_Master!A:A, MATCH( INDEX(Pack_Master!B:B, MATCH(D71, Pack_Master!A:A, 0)), Product_Master!B:B, 0 ) ))} -> Apparel_Accessories_Winter | C71: BANDANA-HANKY-PAISLEY-PURPLE | D71: BANDANA-HANKY-PAISLEY-PURPLE | E71: LIVE | F71: B09FJD5NJY
A72: Amazon | B72: {=IF(D72="","", INDEX(Product_Master!A:A, MATCH( INDEX(Pack_Master!B:B, MATCH(D72, Pack_Master!A:A, 0)), Product_Master!B:B, 0 ) ))} -> Apparel_Accessories_Winter | C72: BANDANA-HANKY-PAISLEY-RED | D72: BANDANA-HANKY-PAISLEY-RED | E72: LIVE | F72: B09DXJ9C1J
A73: Amazon | B73: {=IF(D73="","", INDEX(Product_Master!A:A, MATCH( INDEX(Pack_Master!B:B, MATCH(D73, Pack_Master!A:A, 0)), Product_Master!B:B, 0 ) ))} -> Apparel_Accessories_Winter | C73: BANDANA-HANKY-PAISLEY-TURQUOISE | D73: BANDANA-HANKY-PAISLEY-TURQUOISE | E73: LIVE | F73: B09FJCW1MX
A74: Amazon | B74: {=IF(D74="","", INDEX(Product_Master!A:A, MATCH( INDEX(Pack_Master!B:B, MATCH(D74, Pack_Master!A:A, 0)), Product_Master!B:B, 0 ) ))} -> Apparel_Accessories_Winter | C74: BANDANA-HANKY-PAISLEY-WHITE | D74: BANDANA-HANKY-PAISLEY-WHITE | E74: LIVE | F74: B09DXHDRJV
A75: Amazon | B75: {=IF(D75="","", INDEX(Product_Master!A:A, MATCH( INDEX(Pack_Master!B:B, MATCH(D75, Pack_Master!A:A, 0)), Product_Master!B:B, 0 ) ))} -> Apparel_Accessories_Winter | C75: BANDANA-HANKY-PAISLEY-YELLOW | D75: BANDANA-HANKY-PAISLEY-YELLOW | E75: LIVE | F75: B0BNNGY2SM
A76: Amazon | B76: {=IF(D76="","", INDEX(Product_Master!A:A, MATCH( INDEX(Pack_Master!B:B, MATCH(D76, Pack_Master!A:A, 0)), Product_Master!B:B, 0 ) ))} -> Apparel_Accessories_Winter | C76: BANDANA-HANKY-PAISLEYPO3-BLACKBLUEORANGE | D76: BANDANA-HANKY-PAISLEYPO3-BLACKBLUEORANGE | E76: LIVE | F76: 6161142043042
A77: Amazon | B77: {=IF(D77="","", INDEX(Product_Master!A:A, MATCH( INDEX(Pack_Master!B:B, MATCH(D77, Pack_Master!A:A, 0)), Product_Master!B:B, 0 ) ))} -> Apparel_Accessories_Winter | C77: BANDANA-HANKY-PAISLEYPO3-BLACKNAVYWHITE | D77: BANDANA-HANKY-PAISLEYPO3-BLACKNAVYWHITE | E77: LIVE | F77: 6161142044339
A78: Amazon | B78: {=IF(D78="","", INDEX(Product_Master!A:A, MATCH( INDEX(Pack_Master!B:B, MATCH(D78, Pack_Master!A:A, 0)), Product_Master!B:B, 0 ) ))} -> Apparel_Accessories_Winter | C78: BANDANA-HANKY-PAISLEYPO3-BLACKREDWHITE | D78: BANDANA-HANKY-PAISLEYPO3-BLACKREDWHITE | E78: LIVE | F78: 6161142045008
A79: Amazon | B79: {=IF(D79="","", INDEX(Product_Master!A:A, MATCH( INDEX(Pack_Master!B:B, MATCH(D79, Pack_Master!A:A, 0)), Product_Master!B:B, 0 ) ))} -> Apparel_Accessories_Winter | C79: BANDANA-HANKY-PAISLEYPO3-ORANGENAVYWHITE | D79: BANDANA-HANKY-PAISLEYPO3-ORANGENAVYWHITE | E79: LIVE | F79: 6161142043769
...

Sheet Product_Master
A1: Category | B1: Master_SKU | C1: Suppier_Code | D1: Supplier | E1: Mfg_Cost | F1: Unit_Box_Cost | G1: Labeling_Labor | H1: Inbound_Transport | I1: Total_Unit_COGS | J1: HSN | K1: GST_Rate | L1: Brand | M1: Lifecycle_Status
A2: Apparel_Caps_Beanies | B2: BEANIE-FOLD-2PLAIN-BLUE | C2: tbd | D2: Dearex Hosiery Factory | E2: 99 | F2: 5 | G2: 2 | H2: 1 | I2: =ROUND(E2 + F2 + G2 + H2, 2) -> 107 | K2: 5 | M2: Active
A3: Apparel_Caps_Beanies | B3: BEANIE-FOLD-2PLAIN-BROWN | C3: tbd | D3: Dearex Hosiery Factory | E3: 99 | F3: 5 | G3: 2 | H3: 1 | I3: =ROUND(E3 + F3 + G3 + H3, 2) -> 107 | K3: 5 | M3: Active
A4: Apparel_Caps_Beanies | B4: BEANIE-FOLD-2PLAIN-GREEN | C4: tbd | D4: Dearex Hosiery Factory | E4: 99 | F4: 5 | G4: 2 | H4: 1 | I4: =ROUND(E4 + F4 + G4 + H4, 2) -> 107 | K4: 5 | M4: Active
A5: Apparel_Caps_Beanies | B5: BEANIE-FOLD-2PLAIN-MAROON | C5: tbd | D5: Dearex Hosiery Factory | E5: 99 | F5: 5 | G5: 2 | H5: 1 | I5: =ROUND(E5 + F5 + G5 + H5, 2) -> 107 | K5: 5 | M5: Active
A6: Apparel_Caps_Beanies | B6: BEANIE-FOLD-2PLAIN-OLIVE | C6: tbd | D6: Dearex Hosiery Factory | E6: 99 | F6: 5 | G6: 2 | H6: 1 | I6: =ROUND(E6 + F6 + G6 + H6, 2) -> 107 | K6: 5 | M6: Active
A7: Apparel_Caps_Beanies | B7: BEANIE-FOLD-2PLAIN-YELLOW | C7: tbd | D7: Dearex Hosiery Factory | E7: 99 | F7: 5 | G7: 2 | H7: 1 | I7: =ROUND(E7 + F7 + G7 + H7, 2) -> 107 | K7: 5 | M7: Active
A8: Apparel_Caps_Beanies | B8: BEANIE-FOLD-BINGO-BLUE | C8: tbd | D8: Dearex Hosiery Factory | E8: 99 | F8: 5 | G8: 2 | H8: 1 | I8: =ROUND(E8 + F8 + G8 + H8, 2) -> 107 | K8: 5 | M8: Active
A9: Apparel_Caps_Beanies | B9: BEANIE-FOLD-BINGO-BRICK | C9: tbd | D9: Dearex Hosiery Factory | E9: 99 | F9: 5 | G9: 2 | H9: 1 | I9: =ROUND(E9 + F9 + G9 + H9, 2) -> 107 | K9: 5 | M9: Active
A10: Apparel_Caps_Beanies | B10: BEANIE-FOLD-BINGO-BROWN | C10: tbd | D10: Dearex Hosiery Factory | E10: 99 | F10: 5 | G10: 2 | H10: 1 | I10: =ROUND(E10 + F10 + G10 + H10, 2) -> 107 | K10: 5 | M10: Active
A11: Apparel_Caps_Beanies | B11: BEANIE-FOLD-BINGO-GREEN | C11: tbd | D11: Dearex Hosiery Factory | E11: 99 | F11: 5 | G11: 2 | H11: 1 | I11: =ROUND(E11 + F11 + G11 + H11, 2) -> 107 | K11: 5 | M11: Active
A12: Apparel_Caps_Beanies | B12: BEANIE-FOLD-BINGO-GREY | C12: tbd | D12: Dearex Hosiery Factory | E12: 99 | F12: 5 | G12: 2 | H12: 1 | I12: =ROUND(E12 + F12 + G12 + H12, 2) -> 107 | K12: 5 | M12: Active
A13: Apparel_Caps_Beanies | B13: BEANIE-FOLD-BINGO-LIGHTBROWN | C13: tbd | D13: Dearex Hosiery Factory | E13: 99 | F13: 5 | G13: 2 | H13: 1 | I13: =ROUND(E13 + F13 + G13 + H13, 2) -> 107 | K13: 5 | M13: Active
A14: Apparel_Caps_Beanies | B14: BEANIE-FOLD-BRAND-BLUE | C14: Brand Fold Fur | D14: Dearex Hosiery Factory | E14: 99 | F14: 5 | G14: 2 | H14: 1 | I14: =ROUND(E14 + F14 + G14 + H14, 2) -> 107 | K14: 5
A15: Apparel_Caps_Beanies | B15: BEANIE-FOLD-BRAND-GREEN | C15: Brand Fold Fur | D15: Dearex Hosiery Factory | E15: 99 | F15: 5 | G15: 2 | H15: 1 | I15: =ROUND(E15 + F15 + G15 + H15, 2) -> 107 | K15: 5
A16: Apparel_Caps_Beanies | B16: BEANIE-FOLD-BRAND-GREY | C16: Brand Fold Fur | D16: Dearex Hosiery Factory | E16: 99 | F16: 5 | G16: 2 | H16: 1 | I16: =ROUND(E16 + F16 + G16 + H16, 2) -> 107 | K16: 5
A17: Apparel_Caps_Beanies | B17: BEANIE-FOLD-BRAND-LIGHTBROWN | C17: Brand Fold Fur | D17: Dearex Hosiery Factory | E17: 99 | F17: 5 | G17: 2 | H17: 1 | I17: =ROUND(E17 + F17 + G17 + H17, 2) -> 107 | K17: 5
A18: Apparel_Caps_Beanies | B18: BEANIE-FOLD-BRAND-MAROON | C18: Brand Fold Fur | D18: Dearex Hosiery Factory | E18: 99 | F18: 5 | G18: 2 | H18: 1 | I18: =ROUND(E18 + F18 + G18 + H18, 2) -> 107 | K18: 5
A19: Apparel_Caps_Beanies | B19: BEANIE-FOLD-BRAND-SKIN | C19: Brand Fold Fur | D19: Dearex Hosiery Factory | E19: 99 | F19: 5 | G19: 2 | H19: 1 | I19: =ROUND(E19 + F19 + G19 + H19, 2) -> 107 | K19: 5
A20: Apparel_Caps_Beanies | B20: BEANIE-FOLD-CHECK-BLUE | C20: tbd | D20: Dearex Hosiery Factory | E20: 99 | F20: 5 | G20: 2 | H20: 1 | I20: =ROUND(E20 + F20 + G20 + H20, 2) -> 107 | K20: 5 | M20: Active
A21: Apparel_Caps_Beanies | B21: BEANIE-FOLD-CHECK-GREY | C21: tbd | D21: Dearex Hosiery Factory | E21: 99 | F21: 5 | G21: 2 | H21: 1 | I21: =ROUND(E21 + F21 + G21 + H21, 2) -> 107 | K21: 5 | M21: Active
A22: Apparel_Caps_Beanies | B22: BEANIE-FOLD-CHECK-LIGHTBROWN | C22: tbd | D22: Dearex Hosiery Factory | E22: 99 | F22: 5 | G22: 2 | H22: 1 | I22: =ROUND(E22 + F22 + G22 + H22, 2) -> 107 | K22: 5 | M22: Active
A23: Apparel_Caps_Beanies | B23: BEANIE-FOLD-CHECK-MAROON | C23: tbd | D23: Dearex Hosiery Factory | E23: 99 | F23: 5 | G23: 2 | H23: 1 | I23: =ROUND(E23 + F23 + G23 + H23, 2) -> 107 | K23: 5 | M23: Active
A24: Apparel_Caps_Beanies | B24: BEANIE-FOLD-CHECK-OLIVE | C24: tbd | D24: Dearex Hosiery Factory | E24: 99 | F24: 5 | G24: 2 | H24: 1 | I24: =ROUND(E24 + F24 + G24 + H24, 2) -> 107 | K24: 5 | M24: Active
A25: Apparel_Caps_Beanies | B25: BEANIE-FOLD-KING-ASHGREEN | C25: tbd | D25: Dearex Hosiery Factory | E25: 99 | F25: 5 | G25: 2 | H25: 1 | I25: =ROUND(E25 + F25 + G25 + H25, 2) -> 107 | K25: 5
A26: Apparel_Caps_Beanies | B26: BEANIE-FOLD-KING-BLUE | C26: tbd | D26: Dearex Hosiery Factory | E26: 99 | F26: 5 | G26: 2 | H26: 1 | I26: =ROUND(E26 + F26 + G26 + H26, 2) -> 107 | K26: 5 | M26: Active
A27: Apparel_Caps_Beanies | B27: BEANIE-FOLD-KING-BROWN | C27: tbd | D27: Dearex Hosiery Factory | E27: 99 | F27: 5 | G27: 2 | H27: 1 | I27: =ROUND(E27 + F27 + G27 + H27, 2) -> 107 | K27: 5 | M27: Active
A28: Apparel_Caps_Beanies | B28: BEANIE-FOLD-KING-GREEN | C28: tbd | D28: Dearex Hosiery Factory | E28: 99 | F28: 5 | G28: 2 | H28: 1 | I28: =ROUND(E28 + F28 + G28 + H28, 2) -> 107 | K28: 5 | M28: Active
A29: Apparel_Caps_Beanies | B29: BEANIE-FOLD-KING-GREY | C29: tbd | D29: Dearex Hosiery Factory | E29: 99 | F29: 5 | G29: 2 | H29: 1 | I29: =ROUND(E29 + F29 + G29 + H29, 2) -> 107 | K29: 5 | M29: Active
A30: Apparel_Caps_Beanies | B30: BEANIE-FOLD-KING-LIGHT GREEN | C30: tbd | D30: Dearex Hosiery Factory | E30: 99 | F30: 5 | G30: 2 | H30: 1 | I30: =ROUND(E30 + F30 + G30 + H30, 2) -> 107 | K30: 5 | M30: Active
A31: Apparel_Caps_Beanies | B31: BEANIE-FOLD-KING-LIGHTGREEN | C31: tbd | D31: Dearex Hosiery Factory | I31: =ROUND(E31 + F31 + G31 + H31, 2) -> 0 | K31: 5
A32: Apparel_Caps_Beanies | B32: BEANIE-FOLD-KING-MAROON | C32: tbd | D32: Dearex Hosiery Factory | E32: 99 | F32: 5 | G32: 2 | H32: 1 | I32: =ROUND(E32 + F32 + G32 + H32, 2) -> 107 | K32: 5 | M32: Active
A33: Apparel_Caps_Beanies | B33: BEANIE-FOLD-PLAIN-BLACK | C33: tbd | D33: Dearex Hosiery Factory | E33: 99 | F33: 5 | G33: 2 | H33: 1 | I33: =ROUND(E33 + F33 + G33 + H33, 2) -> 107 | K33: 5
A34: Apparel_Caps_Beanies | B34: BEANIE-FOLD-PLAIN-BLUE | C34: tbd | D34: Dearex Hosiery Factory | E34: 99 | F34: 5 | G34: 2 | H34: 1 | I34: =ROUND(E34 + F34 + G34 + H34, 2) -> 107 | K34: 5
A35: Apparel_Caps_Beanies | B35: BEANIE-FOLD-PLAIN-DARKGREEN | C35: tbd | D35: Dearex Hosiery Factory | E35: 99 | F35: 5 | G35: 2 | H35: 1 | I35: =ROUND(E35 + F35 + G35 + H35, 2) -> 107 | K35: 5
A36: Apparel_Caps_Beanies | B36: BEANIE-FOLD-PLAIN-GREEN | C36: tbd | D36: Dearex Hosiery Factory | E36: 99 | F36: 5 | G36: 2 | H36: 1 | I36: =ROUND(E36 + F36 + G36 + H36, 2) -> 107 | K36: 5
A37: Apparel_Caps_Beanies | B37: BEANIE-FOLD-PLAIN-GREY | C37: tbd | D37: Dearex Hosiery Factory | E37: 99 | F37: 5 | G37: 2 | H37: 1 | I37: =ROUND(E37 + F37 + G37 + H37, 2) -> 107 | K37: 5
A38: Apparel_Caps_Beanies | B38: BEANIE-FOLD-PLAIN-OLIVE | C38: tbd | E38: 99 | F38: 5 | G38: 2 | H38: 1 | I38: =ROUND(E38 + F38 + G38 + H38, 2) -> 107 | K38: 5
A39: Apparel_Caps_Beanies | B39: BEANIE-FOLD-PLAIN-SKIN | C39: tbd | E39: 99 | F39: 5 | G39: 2 | H39: 1 | I39: =ROUND(E39 + F39 + G39 + H39, 2) -> 107 | K39: 5
A40: Apparel_Caps_Beanies | B40: BEANIE-FUR-SHORT-RED | C40: tbd | E40: 99 | F40: 5 | G40: 2 | H40: 1 | I40: =ROUND(E40 + F40 + G40 + H40, 2) -> 107 | K40: 5 | M40: Active
...

Sheet Pack_Master
A1: Pack_SKU | B1: Master_SKU | C1: Pack_Qty | D1: Packaging_COGS | E1: Final_L | F1: Final_W | G1: Final_H | H1: Final_Wt_Kg
A2: BEANIE-FOLD-2PLAIN-BLUE | B2: BEANIE-FOLD-2PLAIN-BLUE | C2: 1 | D2: 2 | E2: 25 | F2: 25 | G2: 3 | H2: 0.5
A3: BEANIE-FOLD-2PLAIN-BROWN | B3: BEANIE-FOLD-2PLAIN-BROWN | C3: 1 | D3: 2 | E3: 25 | F3: 25 | G3: 3 | H3: 0.5
A4: BEANIE-FOLD-2PLAIN-GREEN | B4: BEANIE-FOLD-2PLAIN-GREEN | C4: 1 | D4: 2 | E4: 25 | F4: 25 | G4: 3 | H4: 0.5
A5: BEANIE-FOLD-2PLAIN-MAROON | B5: BEANIE-FOLD-2PLAIN-MAROON | C5: 1 | D5: 2 | E5: 25 | F5: 25 | G5: 3 | H5: 0.5
A6: BEANIE-FOLD-2PLAIN-OLIVE | B6: BEANIE-FOLD-2PLAIN-OLIVE | C6: 1 | D6: 2 | E6: 25 | F6: 25 | G6: 3 | H6: 0.5
A7: BEANIE-FOLD-2PLAIN-YELLOW | B7: BEANIE-FOLD-2PLAIN-YELLOW | C7: 1 | D7: 2 | E7: 25 | F7: 25 | G7: 3 | H7: 0.5
A8: BEANIE-FOLD-BINGO-BLUE | B8: BEANIE-FOLD-BINGO-BLUE | C8: 1 | D8: 2 | E8: 25 | F8: 25 | G8: 3 | H8: 0.5
A9: BEANIE-FOLD-BINGO-BRICK | B9: BEANIE-FOLD-BINGO-BRICK | C9: 1 | D9: 2 | E9: 25 | F9: 25 | G9: 3 | H9: 0.5
A10: BEANIE-FOLD-BINGO-BROWN | B10: BEANIE-FOLD-BINGO-BROWN | C10: 1 | D10: 2 | E10: 25 | F10: 25 | G10: 3 | H10: 0.5
A11: BEANIE-FOLD-BINGO-GREEN | B11: BEANIE-FOLD-BINGO-GREEN | C11: 1 | D11: 2 | E11: 25 | F11: 25 | G11: 3 | H11: 0.5
A12: BEANIE-FOLD-BINGO-GREY | B12: BEANIE-FOLD-BINGO-GREY | C12: 1 | D12: 2 | E12: 25 | F12: 25 | G12: 3 | H12: 0.5
A13: BEANIE-FOLD-BINGO-LIGHTBROWN | B13: BEANIE-FOLD-BINGO-LIGHTBROWN | C13: 1 | D13: 2 | E13: 25 | F13: 25 | G13: 3 | H13: 0.5
... A429: CAP-GOLF-CHARCOAL | B429: CAP-GOLF-CHARCOAL | C429: 1 | D429: 0 | E429: 0 | F429: 0 | G429: 0 | H429: 0

Sheet Pricing_&_Profit_Control
A1: Marketplace | B1: Category | C1: Channel_SKU | D1: Pack_SKU | E1: Selling_Price | F1: Total_COGS | G1: Volumetric_Wt | H1: Billable_Weight | I1: Shipping_Fee | J1: Platform_Fees | K1: Net_Profit | L1: Profit_Margin
A2: Amazon | B2: {=IF(D2="","", INDEX(Product_Master!A:A, MATCH( INDEX(Pack_Master!B:B, MATCH(D2, Pack_Master!A:A, 0)), Product_Master!B:B, 0 ) ))} -> #N/A | C2: ABC1 | D2: ABC-PK1 | E2: 999 | F2: {=IFERROR( VALUE( INDEX(Product_Master!$I:$I, MATCH( INDEX(Pack_Master!$B:$B, MATCH($D2, Pack_Master!$A:$A, 0)), Product_Master!$B:$B, 0) )) * VALUE( INDEX(Pack_Master!$C:$C, MATCH($D2, Pack_Master!$A:$A, 0)) ) + VALUE( INDEX(Pack_Master!$D:$D, MATCH($D2, Pack_Master!$A:$A, 0)) ), "")} | G2: {=IFERROR( ( INDEX(Pack_Master!E:E, MATCH($D2, Pack_Master!A:A, 0)) * INDEX(Pack_Master!F:F, MATCH($D2, Pack_Master!A:A, 0)) * INDEX(Pack_Master!G:G, MATCH($D2, Pack_Master!A:A, 0)) ) / INDEX(Config!C:C, MATCH($A2, Config!A:A, 0)), "")} | H2: {=MAX( INDEX(Pack_Master!H:H, MATCH($D2, Pack_Master!A:A, 0)), IFERROR(G2, 0) )} -> #N/A | I2: =IFERROR(__xludf.DUMMYFUNCTION("IFERROR( INDEX( FILTER(Shipping_Rate_Card!B:F, Shipping_Rate_Card!A:A=$A2), MATCH($H2, FILTER(Shipping_Rate_Card!B:B, Shipping_Rate_Card!A:A=$A2), 1), IF( INDEX(Config!B:B, MATCH($A2, Config!A:A, 0))=""Local"", 2, IF( INDEX(Config!B:B, MATC"&"H($A2, Config!A:A, 0))=""Regional"", 3, 4 ) ) ), """") "),"") | J2: =IFERROR(__xludf.DUMMYFUNCTION("IFERROR( ( E2 * INDEX(FILTER(Pricing_Rules!E:E, Pricing_Rules!A:A=A2, Pricing_Rules!B:B=B2, Pricing_Rules!C:C<=E2, Pricing_Rules!D:D>=E2), 1) + INDEX(FILTER(Pricing_Rules!F:F, Pricing_Rules!A:A=A2, Pricing_Rules!B:B=B2, Pricing_Rules!C:C<=E2, Pricing_"&"Rules!D:D>=E2), 1) ) * (1 + IFERROR( INDEX(Config!D:D, MATCH(A2, Config!A:A, 0)), 0 )), """") "),"") | K2: =IFERROR(E2 - F2 - I2 - J2, "") -> 999 | L2: =IFERROR(K2 / E2, "") -> 1
A3: Amazon | B3: {=IF(D3="","", INDEX(Product_Master!A:A, MATCH( INDEX(Pack_Master!B:B, MATCH(D3, Pack_Master!A:A, 0)), Product_Master!B:B, 0 ) ))} -> #N/A | C3: ABC_Pack2 | D3: ABC-PK2 | E3: 1899 | F3: {=IFERROR( VALUE( INDEX(Product_Master!$I:$I, MATCH( INDEX(Pack_Master!$B:$B, MATCH($D3, Pack_Master!$A:$A, 0)), Product_Master!$B:$B, 0) )) * VALUE( INDEX(Pack_Master!$C:$C, MATCH($D3, Pack_Master!$A:$A, 0)) ) + VALUE( INDEX(Pack_Master!$D:$D, MATCH($D3, Pack_Master!$A:$A, 0)) ), "")} | G3: {=IFERROR( ( INDEX(Pack_Master!E:E, MATCH($D3, Pack_Master!A:A, 0)) * INDEX(Pack_Master!F:F, MATCH($D3, Pack_Master!A:A, 0)) * INDEX(Pack_Master!G:G, MATCH($D3, Pack_Master!A:A, 0)) ) / INDEX(Config!C:C, MATCH($A3, Config!A:A, 0)), "")} | H3: {=MAX( INDEX(Pack_Master!H:H, MATCH($D3, Pack_Master!A:A, 0)), IFERROR(G3, 0) )} -> #N/A | I3: =IFERROR(__xludf.DUMMYFUNCTION("IFERROR( INDEX( FILTER(Shipping_Rate_Card!B:F, Shipping_Rate_Card!A:A=$A3), MATCH($H3, FILTER(Shipping_Rate_Card!B:B, Shipping_Rate_Card!A:A=$A3), 1), IF( INDEX(Config!B:B, MATCH($A3, Config!A:A, 0))=""Local"", 2, IF( INDEX(Config!B:B, MATC"&"H($A3, Config!A:A, 0))=""Regional"", 3, 4 ) ) ), """") "),"") | J3: =IFERROR(__xludf.DUMMYFUNCTION("IFERROR( ( E3 * INDEX(FILTER(Pricing_Rules!E:E, Pricing_Rules!A:A=A3, Pricing_Rules!B:B=B3, Pricing_Rules!C:C<=E3, Pricing_Rules!D:D>=E3), 1) + INDEX(FILTER(Pricing_Rules!F:F, Pricing_Rules!A:A=A3, Pricing_Rules!B:B=B3, Pricing_Rules!C:C<=E3, Pricing_"&"Rules!D:D>=E3), 1) ) * (1 + IFERROR( INDEX(Config!D:D, MATCH(A3, Config!A:A, 0)), 0 )), """") "),"") | K3: =IFERROR(E3 - F3 - I3 - J3, "") -> 1899 | L3: =IFERROR(K3 / E3, "") -> 1
A4: Amazon | B4: {=IF(D4="","", INDEX(Product_Master!A:A, MATCH( INDEX(Pack_Master!B:B, MATCH(D4, Pack_Master!A:A, 0)), Product_Master!B:B, 0 ) ))} -> Apparel_Caps_Beanies | C4: BEANIE-FOLD-2PLAIN-BLUE | D4: BEANIE-FOLD-2PLAIN-BLUE | E4: 299 | F4: {=IFERROR( VALUE( INDEX(Product_Master!$I:$I, MATCH( INDEX(Pack_Master!$B:$B, MATCH($D4, Pack_Master!$A:$A, 0)), Product_Master!$B:$B, 0) )) * VALUE( INDEX(Pack_Master!$C:$C, MATCH($D4, Pack_Master!$A:$A, 0)) ) + VALUE( INDEX(Pack_Master!$D:$D, MATCH($D4, Pack_Master!$A:$A, 0)) ), "")} -> 109 | G4: {=IFERROR( ( INDEX(Pack_Master!E:E, MATCH($D4, Pack_Master!A:A, 0)) * INDEX(Pack_Master!F:F, MATCH($D4, Pack_Master!A:A, 0)) * INDEX(Pack_Master!G:G, MATCH($D4, Pack_Master!A:A, 0)) ) / INDEX(Config!C:C, MATCH($A4, Config!A:A, 0)), "")} -> 0.375 | H4: {=MAX( INDEX(Pack_Master!H:H, MATCH($D4, Pack_Master!A:A, 0)), IFERROR(G4, 0) )} -> 0.5 | I4: =IFERROR(__xludf.DUMMYFUNCTION("IFERROR( INDEX( FILTER(Shipping_Rate_Card!B:F, Shipping_Rate_Card!A:A=$A4), MATCH($H4, FILTER(Shipping_Rate_Card!B:B, Shipping_Rate_Card!A:A=$A4), 1), IF( INDEX(Config!B:B, MATCH($A4, Config!A:A, 0))=""Local"", 2, IF( INDEX(Config!B:B, MATC"&"H($A4, Config!A:A, 0))=""Regional"", 3, 4 ) ) ), """") "),67.0) -> 67 | J4: =IFERROR(__xludf.DUMMYFUNCTION("IFERROR( ( E4 * INDEX(FILTER(Pricing_Rules!E:E, Pricing_Rules!A:A=A4, Pricing_Rules!B:B=B4, Pricing_Rules!C:C<=E4, Pricing_Rules!D:D>=E4), 1) + INDEX(FILTER(Pricing_Rules!F:F, Pricing_Rules!A:A=A4, Pricing_Rules!B:B=B4, Pricing_Rules!C:C<=E4, Pricing_"&"Rules!D:D>=E4), 1) ) * (1 + IFERROR( INDEX(Config!D:D, MATCH(A4, Config!A:A, 0)), 0 )), """") "),5.8999999999999995) -> 5.9 | K4: =IFERROR(E4 - F4 - I4 - J4, "") -> 117.1 | L4: =IFERROR(K4 / E4, "") -> 0.3916388
A5: Amazon | B5: {=IF(D5="","", INDEX(Product_Master!A:A, MATCH( INDEX(Pack_Master!B:B, MATCH(D5, Pack_Master!A:A, 0)), Product_Master!B:B, 0 ) ))} -> Apparel_Caps_Beanies | C5: BEANIE-FOLD-2PLAIN-BROWN | D5: BEANIE-FOLD-2PLAIN-BROWN | E5: 299 | F5: {=IFERROR( VALUE( INDEX(Product_Master!$I:$I, MATCH( INDEX(Pack_Master!$B:$B, MATCH($D5, Pack_Master!$A:$A, 0)), Product_Master!$B:$B, 0) )) * VALUE( INDEX(Pack_Master!$C:$C, MATCH($D5, Pack_Master!$A:$A, 0)) ) + VALUE( INDEX(Pack_Master!$D:$D, MATCH($D5, Pack_Master!$A:$A, 0)) ), "")} -> 109 | G5: {=IFERROR( ( INDEX(Pack_Master!E:E, MATCH($D5, Pack_Master!A:A, 0)) * INDEX(Pack_Master!F:F, MATCH($D5, Pack_Master!A:A, 0)) * INDEX(Pack_Master!G:G, MATCH($D5, Pack_Master!A:A, 0)) ) / INDEX(Config!C:C, MATCH($A5, Config!A:A, 0)), "")} -> 0.375 | H5: {=MAX( INDEX(Pack_Master!H:H, MATCH($D5, Pack_Master!A:A, 0)), IFERROR(G5, 0) )} -> 0.5 | I5: =IFERROR(__xludf.DUMMYFUNCTION("IFERROR( INDEX( FILTER(Shipping_Rate_Card!B:F, Shipping_Rate_Card!A:A=$A5), MATCH($H5, FILTER(Shipping_Rate_Card!B:B, Shipping_Rate_Card!A:A=$A5), 1), IF( INDEX(Config!B:B, MATCH($A5, Config!A:A, 0))=""Local"", 2, IF( INDEX(Config!B:B, MATC"&"H($A5, Config!A:A, 0))=""Regional"", 3, 4 ) ) ), """") "),67.0) -> 67 | J5: =IFERROR(__xludf.DUMMYFUNCTION("IFERROR( ( E5 * INDEX(FILTER(Pricing_Rules!E:E, Pricing_Rules!A:A=A5, Pricing_Rules!B:B=B5, Pricing_Rules!C:C<=E5, Pricing_Rules!D:D>=E5), 1) + INDEX(FILTER(Pricing_Rules!F:F, Pricing_Rules!A:A=A5, Pricing_Rules!B:B=B5, Pricing_Rules!C:C<=E5, Pricing_"&"Rules!D:D>=E5), 1) ) * (1 + IFERROR( INDEX(Config!D:D, MATCH(A5, Config!A:A, 0)), 0 )), """") "),5.8999999999999995) -> 5.9 | K5: =IFERROR(E5 - F5 - I5 - J5, "") -> 117.1 | L5: =IFERROR(K5 / E5, "") -> 0.3916388
A6: Amazon | B6: {=IF(D6="","", INDEX(Product_Master!A:A, MATCH( INDEX(Pack_Master!B:B, MATCH(D6, Pack_Master!A:A, 0)), Product_Master!B:B, 0 ) ))} -> Apparel_Caps_Beanies | C6: BEANIE-FOLD-2PLAIN-GREEN | D6: BEANIE-FOLD-2PLAIN-GREEN | E6: 299 | F6: {=IFERROR( VALUE( INDEX(Product_Master!$I:$I, MATCH( INDEX(Pack_Master!$B:$B, MATCH($D6, Pack_Master!$A:$A, 0)), Product_Master!$B:$B, 0) )) * VALUE( INDEX(Pack_Master!$C:$C, MATCH($D6, Pack_Master!$A:$A, 0)) ) + VALUE( INDEX(Pack_Master!$D:$D, MATCH($D6, Pack_Master!$A:$A, 0)) ), "")} -> 109 | G6: {=IFERROR( ( INDEX(Pack_Master!E:E, MATCH($D6, Pack_Master!A:A, 0)) * INDEX(Pack_Master!F:F, MATCH($D6, Pack_Master!A:A, 0)) * INDEX(Pack_Master!G:G, MATCH($D6, Pack_Master!A:A, 0)) ) / INDEX(Config!C:C, MATCH($A6, Config!A:A, 0)), "")} -> 0.375 | H6: {=MAX( INDEX(Pack_Master!H:H, MATCH($D6, Pack_Master!A:A, 0)), IFERROR(G6, 0) )} -> 0.5 | I6: =IFERROR(__xludf.DUMMYFUNCTION("IFERROR( INDEX( FILTER(Shipping_Rate_Card!B:F, Shipping_Rate_Card!A:A=$A6), MATCH($H6, FILTER(Shipping_Rate_Card!B:B, Shipping_Rate_Card!A:A=$A6), 1), IF( INDEX(Config!B:B, MATCH($A6, Config!A:A, 0))=""Local"", 2, IF( INDEX(Config!B:B, MATC"&"H($A6, Config!A:A, 0))=""Regional"", 3, 4 ) ) ), """") "),67.0) -> 67 | J6: =IFERROR(__xludf.DUMMYFUNCTION("IFERROR( ( E6 * INDEX(FILTER(Pricing_Rules!E:E, Pricing_Rules!A:A=A6, Pricing_Rules!B:B=B6, Pricing_Rules!C:C<=E6, Pricing_Rules!D:D>=E6), 1) + INDEX(FILTER(Pricing_Rules!F:F, Pricing_Rules!A:A=A6, Pricing_Rules!B:B=B6, Pricing_Rules!C:C<=E6, Pricing_"&"Rules!D:D>=E6), 1) ) * (1 + IFERROR( INDEX(Config!D:D, MATCH(A6, Config!A:A, 0)), 0 )), """") "),5.8999999999999995) -> 5.9 | K6: =IFERROR(E6 - F6 - I6 - J6, "") -> 117.1 | L6: =IFERROR(K6 / E6, "") -> 0.3916388
A7: Amazon | B7: {=IF(D7="","", INDEX(Product_Master!A:A, MATCH( INDEX(Pack_Master!B:B, MATCH(D7, Pack_Master!A:A, 0)), Product_Master!B:B, 0 ) ))} -> Apparel_Caps_Beanies | C7: BEANIE-FOLD-2PLAIN-MAROON | D7: BEANIE-FOLD-2PLAIN-MAROON | E7: 299 | F7: {=IFERROR( VALUE( INDEX(Product_Master!$I:$I, MATCH( INDEX(Pack_Master!$B:$B, MATCH($D7, Pack_Master!$A:$A, 0)), Product_Master!$B:$B, 0) )) * VALUE( INDEX(Pack_Master!$C:$C, MATCH($D7, Pack_Master!$A:$A, 0)) ) + VALUE( INDEX(Pack_Master!$D:$D, MATCH($D7, Pack_Master!$A:$A, 0)) ), "")} -> 109 | G7: {=IFERROR( ( INDEX(Pack_Master!E:E, MATCH($D7, Pack_Master!A:A, 0)) * INDEX(Pack_Master!F:F, MATCH($D7, Pack_Master!A:A, 0)) * INDEX(Pack_Master!G:G, MATCH($D7, Pack_Master!A:A, 0)) ) / INDEX(Config!C:C, MATCH($A7, Config!A:A, 0)), "")} -> 0.375 | H7: {=MAX( INDEX(Pack_Master!H:H, MATCH($D7, Pack_Master!A:A, 0)), IFERROR(G7, 0) )} -> 0.5 | I7: =IFERROR(__xludf.DUMMYFUNCTION("IFERROR( INDEX( FILTER(Shipping_Rate_Card!B:F, Shipping_Rate_Card!A:A=$A7), MATCH($H7, FILTER(Shipping_Rate_Card!B:B, Shipping_Rate_Card!A:A=$A7), 1), IF( INDEX(Config!B:B, MATCH($A7, Config!A:A, 0))=""Local"", 2, IF( INDEX(Config!B:B, MATC"&"H($A7, Config!A:A, 0))=""Regional"", 3, 4 ) ) ), """") "),67.0) -> 67 | J7: =IFERROR(__xludf.DUMMYFUNCTION("IFERROR( ( E7 * INDEX(FILTER(Pricing_Rules!E:E, Pricing_Rules!A:A=A7, Pricing_Rules!B:B=B7, Pricing_Rules!C:C<=E7, Pricing_Rules!D:D>=E7), 1) + INDEX(FILTER(Pricing_Rules!F:F, Pricing_Rules!A:A=A7, Pricing_Rules!B:B=B7, Pricing_Rules!C:C<=E7, Pricing_"&"Rules!D:D>=E7), 1) ) * (1 + IFERROR( INDEX(Config!D:D, MATCH(A7, Config!A:A, 0)), 0 )), """") "),5.8999999999999995) -> 5.9 | K7: =IFERROR(E7 - F7 - I7 - J7, "") -> 117.1 | L7: =IFERROR(K7 / E7, "") -> 0.3916388
A8: Amazon | B8: {=IF(D8="","", INDEX(Product_Master!A:A, MATCH( INDEX(Pack_Master!B:B, MATCH(D8, Pack_Master!A:A, 0)), Product_Master!B:B, 0 ) ))} -> Apparel_Caps_Beanies | C8: BEANIE-FOLD-2PLAIN-OLIVE | D8: BEANIE-FOLD-2PLAIN-OLIVE | E8: 299 | F8: {=IFERROR( VALUE( INDEX(Product_Master!$I:$I, MATCH( INDEX(Pack_Master!$B:$B, MATCH($D8, Pack_Master!$A:$A, 0)), Product_Master!$B:$B, 0) )) * VALUE( INDEX(Pack_Master!$C:$C, MATCH($D8, Pack_Master!$A:$A, 0)) ) + VALUE( INDEX(Pack_Master!$D:$D, MATCH($D8, Pack_Master!$A:$A, 0)) ), "")} -> 109 | G8: {=IFERROR( ( INDEX(Pack_Master!E:E, MATCH($D8, Pack_Master!A:A, 0)) * INDEX(Pack_Master!F:F, MATCH($D8, Pack_Master!A:A, 0)) * INDEX(Pack_Master!G:G, MATCH($D8, Pack_Master!A:A, 0)) ) / INDEX(Config!C:C, MATCH($A8, Config!A:A, 0)), "")} -> 0.375 | H8: {=MAX( INDEX(Pack_Master!H:H, MATCH($D8, Pack_Master!A:A, 0)), IFERROR(G8, 0) )} -> 0.5 | I8: =IFERROR(__xludf.DUMMYFUNCTION("IFERROR( INDEX( FILTER(Shipping_Rate_Card!B:F, Shipping_Rate_Card!A:A=$A8), MATCH($H8, FILTER(Shipping_Rate_Card!B:B, Shipping_Rate_Card!A:A=$A8), 1), IF( INDEX(Config!B:B, MATCH($A8, Config!A:A, 0))=""Local"", 2, IF( INDEX(Config!B:B, MATC"&"H($A8, Config!A:A, 0))=""Regional"", 3, 4 ) ) ), """") "),67.0) -> 67 | J8: =IFERROR(__xludf.DUMMYFUNCTION("IFERROR( ( E8 * INDEX(FILTER(Pricing_Rules!E:E, Pricing_Rules!A:A=A8, Pricing_Rules!B:B=B8, Pricing_Rules!C:C<=E8, Pricing_Rules!D:D>=E8), 1) + INDEX(FILTER(Pricing_Rules!F:F, Pricing_Rules!A:A=A8, Pricing_Rules!B:B=B8, Pricing_Rules!C:C<=E8, Pricing_"&"Rules!D:D>=E8), 1) ) * (1 + IFERROR( INDEX(Config!D:D, MATCH(A8, Config!A:A, 0)), 0 )), """") "),5.8999999999999995) -> 5.9 | K8: =IFERROR(E8 - F8 - I8 - J8, "") -> 117.1 | L8: =IFERROR(K8 / E8, "") -> 0.3916388
A9: Amazon | B9: {=IF(D9="","", INDEX(Product_Master!A:A, MATCH( INDEX(Pack_Master!B:B, MATCH(D9, Pack_Master!A:A, 0)), Product_Master!B:B, 0 ) ))} -> Apparel_Caps_Beanies | C9: BEANIE-FOLD-2PLAIN-YELLOW | D9: BEANIE-FOLD-2PLAIN-YELLOW | E9: 299 | F9: {=IFERROR( VALUE( INDEX(Product_Master!$I:$I, MATCH( INDEX(Pack_Master!$B:$B, MATCH($D9, Pack_Master!$A:$A, 0)), Product_Master!$B:$B, 0) )) * VALUE( INDEX(Pack_Master!$C:$C, MATCH($D9, Pack_Master!$A:$A, 0)) ) + VALUE( INDEX(Pack_Master!$D:$D, MATCH($D9, Pack_Master!$A:$A, 0)) ), "")} -> 109 | G9: {=IFERROR( ( INDEX(Pack_Master!E:E, MATCH($D9, Pack_Master!A:A, 0)) * INDEX(Pack_Master!F:F, MATCH($D9, Pack_Master!A:A, 0)) * INDEX(Pack_Master!G:G, MATCH($D9, Pack_Master!A:A, 0)) ) / INDEX(Config!C:C, MATCH($A9, Config!A:A, 0)), "")} -> 0.375 | H9: {=MAX( INDEX(Pack_Master!H:H, MATCH($D9, Pack_Master!A:A, 0)), IFERROR(G9, 0) )} -> 0.5 | I9: =IFERROR(__xludf.DUMMYFUNCTION("IFERROR( INDEX( FILTER(Shipping_Rate_Card!B:F, Shipping_Rate_Card!A:A=$A9), MATCH($H9, FILTER(Shipping_Rate_Card!B:B, Shipping_Rate_Card!A:A=$A9), 1), IF( INDEX(Config!B:B, MATCH($A9, Config!A:A, 0))=""Local"", 2, IF( INDEX(Config!B:B, MATC"&"H($A9, Config!A:A, 0))=""Regional"", 3, 4 ) ) ), """") "),67.0) -> 67 | J9: =IFERROR(__xludf.DUMMYFUNCTION("IFERROR( ( E9 * INDEX(FILTER(Pricing_Rules!E:E, Pricing_Rules!A:A=A9, Pricing_Rules!B:B=B9, Pricing_Rules!C:C<=E9, Pricing_Rules!D:D>=E9), 1) + INDEX(FILTER(Pricing_Rules!F:F, Pricing_Rules!A:A=A9, Pricing_Rules!B:B=B9, Pricing_Rules!C:C<=E9, Pricing_"&"Rules!D:D>=E9), 1) ) * (1 + IFERROR( INDEX(Config!D:D, MATCH(A9, Config!A:A, 0)), 0 )), """") "),5.8999999999999995) -> 5.9 | K9: =IFERROR(E9 - F9 - I9 - J9, "") -> 117.1 | L9: =IFERROR(K9 / E9, "") -> 0.3916388
A10: Amazon | B10: {=IF(D10="","", INDEX(Product_Master!A:A, MATCH( INDEX(Pack_Master!B:B, MATCH(D10, Pack_Master!A:A, 0)), Product_Master!B:B, 0 ) ))} -> Apparel_Caps_Beanies | C10: BEANIE-FOLD-BINGO-BLUE | D10: BEANIE-FOLD-BINGO-BLUE | E10: 299 | F10: {=IFERROR( VALUE( INDEX(Product_Master!$I:$I, MATCH( INDEX(Pack_Master!$B:$B, MATCH($D10, Pack_Master!$A:$A, 0)), Product_Master!$B:$B, 0) )) * VALUE( INDEX(Pack_Master!$C:$C, MATCH($D10, Pack_Master!$A:$A, 0)) ) + VALUE( INDEX(Pack_Master!$D:$D, MATCH($D10, Pack_Master!$A:$A, 0)) ), "")} -> 109 | G10: {=IFERROR( ( INDEX(Pack_Master!E:E, MATCH($D10, Pack_Master!A:A, 0)) * INDEX(Pack_Master!F:F, MATCH($D10, Pack_Master!A:A, 0)) * INDEX(Pack_Master!G:G, MATCH($D10, Pack_Master!A:A, 0)) ) / INDEX(Config!C:C, MATCH($A10, Config!A:A, 0)), "")} -> 0.375 | H10: {=MAX( INDEX(Pack_Master!H:H, MATCH($D10, Pack_Master!A:A, 0)), IFERROR(G10, 0) )} -> 0.5 | I10: =IFERROR(__xludf.DUMMYFUNCTION("IFERROR( INDEX( FILTER(Shipping_Rate_Card!B:F, Shipping_Rate_Card!A:A=$A10), MATCH($H10, FILTER(Shipping_Rate_Card!B:B, Shipping_Rate_Card!A:A=$A10), 1), IF( INDEX(Config!B:B, MATCH($A10, Config!A:A, 0))=""Local"", 2, IF( INDEX(Config!B:B, "&"MATCH($A10, Config!A:A, 0))=""Regional"", 3, 4 ) ) ), """") "),67.0) -> 67 | J10: =IFERROR(__xludf.DUMMYFUNCTION("IFERROR( ( E10 * INDEX(FILTER(Pricing_Rules!E:E, Pricing_Rules!A:A=A10, Pricing_Rules!B:B=B10, Pricing_Rules!C:C<=E10, Pricing_Rules!D:D>=E10), 1) + INDEX(FILTER(Pricing_Rules!F:F, Pricing_Rules!A:A=A10, Pricing_Rules!B:B=B10, Pricing_Rules!C:C<=E10, "&"Pricing_Rules!D:D>=E10), 1) ) * (1 + IFERROR( INDEX(Config!D:D, MATCH(A10, Config!A:A, 0)), 0 )), """") "),5.8999999999999995) -> 5.9 | K10: =IFERROR(E10 - F10 - I10 - J10, "") -> 117.1 | L10: =IFERROR(K10 / E10, "") -> 0.3916388
A11: Amazon | B11: {=IF(D11="","", INDEX(Product_Master!A:A, MATCH( INDEX(Pack_Master!B:B, MATCH(D11, Pack_Master!A:A, 0)), Product_Master!B:B, 0 ) ))} -> Apparel_Caps_Beanies | C11: BEANIE-FOLD-BINGO-BRICK | D11: BEANIE-FOLD-BINGO-BRICK | E11: 299 | F11: {=IFERROR( VALUE( INDEX(Product_Master!$I:$I, MATCH( INDEX(Pack_Master!$B:$B, MATCH($D11, Pack_Master!$A:$A, 0)), Product_Master!$B:$B, 0) )) * VALUE( INDEX(Pack_Master!$C:$C, MATCH($D11, Pack_Master!$A:$A, 0)) ) + VALUE( INDEX(Pack_Master!$D:$D, MATCH($D11, Pack_Master!$A:$A, 0)) ), "")} -> 109 | G11: {=IFERROR( ( INDEX(Pack_Master!E:E, MATCH($D11, Pack_Master!A:A, 0)) * INDEX(Pack_Master!F:F, MATCH($D11, Pack_Master!A:A, 0)) * INDEX(Pack_Master!G:G, MATCH($D11, Pack_Master!A:A, 0)) ) / INDEX(Config!C:C, MATCH($A11, Config!A:A, 0)), "")} -> 0.375 | H11: {=MAX( INDEX(Pack_Master!H:H, MATCH($D11, Pack_Master!A:A, 0)), IFERROR(G11, 0) )} -> 0.5 | I11: =IFERROR(__xludf.DUMMYFUNCTION("IFERROR( INDEX( FILTER(Shipping_Rate_Card!B:F, Shipping_Rate_Card!A:A=$A11), MATCH($H11, FILTER(Shipping_Rate_Card!B:B, Shipping_Rate_Card!A:A=$A11), 1), IF( INDEX(Config!B:B, MATCH($A11, Config!A:A, 0))=""Local"", 2, IF( INDEX(Config!B:B, "&"MATCH($A11, Config!A:A, 0))=""Regional"", 3, 4 ) ) ), """") "),67.0) -> 67 | J11: =IFERROR(__xludf.DUMMYFUNCTION("IFERROR( ( E11 * INDEX(FILTER(Pricing_Rules!E:E, Pricing_Rules!A:A=A11, Pricing_Rules!B:B=B11, Pricing_Rules!C:C<=E11, Pricing_Rules!D:D>=E11), 1) + INDEX(FILTER(Pricing_Rules!F:F, Pricing_Rules!A:A=A11, Pricing_Rules!B:B=B11, Pricing_Rules!C:C<=E11, "&"Pricing_Rules!D:D>=E11), 1) ) * (1 + IFERROR( INDEX(Config!D:D, MATCH(A11, Config!A:A, 0)), 0 )), """") "),5.8999999999999995) -> 5.9 | K11: =IFERROR(E11 - F11 - I11 - J11, "") -> 117.1 | L11: =IFERROR(K11 / E11, "") -> 0.3916388
A12: Amazon | B12: {=IF(D12="","", INDEX(Product_Master!A:A, MATCH( INDEX(Pack_Master!B:B, MATCH(D12, Pack_Master!A:A, 0)), Product_Master!B:B, 0 ) ))} -> Apparel_Caps_Beanies | C12: BEANIE-FOLD-BINGO-BROWN | D12: BEANIE-FOLD-BINGO-BROWN | E12: 299 | F12: {=IFERROR( VALUE( INDEX(Product_Master!$I:$I, MATCH( INDEX(Pack_Master!$B:$B, MATCH($D12, Pack_Master!$A:$A, 0)), Product_Master!$B:$B, 0) )) * VALUE( INDEX(Pack_Master!$C:$C, MATCH($D12, Pack_Master!$A:$A, 0)) ) + VALUE( INDEX(Pack_Master!$D:$D, MATCH($D12, Pack_Master!$A:$A, 0)) ), "")} -> 109 | G12: {=IFERROR( ( INDEX(Pack_Master!E:E, MATCH($D12, Pack_Master!A:A, 0)) * INDEX(Pack_Master!F:F, MATCH($D12, Pack_Master!A:A, 0)) * INDEX(Pack_Master!G:G, MATCH($D12, Pack_Master!A:A, 0)) ) / INDEX(Config!C:C, MATCH($A12, Config!A:A, 0)), "")} -> 0.375 | H12: {=MAX( INDEX(Pack_Master!H:H, MATCH($D12, Pack_Master!A:A, 0)), IFERROR(G12, 0) )} -> 0.5 | I12: =IFERROR(__xludf.DUMMYFUNCTION("IFERROR( INDEX( FILTER(Shipping_Rate_Card!B:F, Shipping_Rate_Card!A:A=$A12), MATCH($H12, FILTER(Shipping_Rate_Card!B:B, Shipping_Rate_Card!A:A=$A12), 1), IF( INDEX(Config!B:B, MATCH($A12, Config!A:A, 0))=""Local"", 2, IF( INDEX(Config!B:B, "&"MATCH($A12, Config!A:A, 0))=""Regional"", 3, 4 ) ) ), """") "),67.0) -> 67 | J12: =IFERROR(__xludf.DUMMYFUNCTION("IFERROR( ( E12 * INDEX(FILTER(Pricing_Rules!E:E, Pricing_Rules!A:A=A12, Pricing_Rules!B:B=B12, Pricing_Rules!C:C<=E12, Pricing_Rules!D:D>=E12), 1) + INDEX(FILTER(Pricing_Rules!F:F, Pricing_Rules!A:A=A12, Pricing_Rules!B:B=B12, Pricing_Rules!C:C<=E12, "&"Pricing_Rules!D:D>=E12), 1) ) * (1 + IFERROR( INDEX(Config!D:D, MATCH(A12, Config!A:A, 0)), 0 )), """") "),5.8999999999999995) -> 5.9 | K12: =IFERROR(E12 - F12 - I12 - J12, "") -> 117.1 | L12: =IFERROR(K12 / E12, "") -> 0.3916388
A13: Amazon | B13: {=IF(D13="","", INDEX(Product_Master!A:A, MATCH( INDEX(Pack_Master!B:B, MATCH(D13, Pack_Master!A:A, 0)), Product_Master!B:B, 0 ) ))} -> Apparel_Caps_Beanies | C13: BEANIE-FOLD-BINGO-GREEN | D13: BEANIE-FOLD-BINGO-GREEN | E13: 299 | F13: {=IFERROR( VALUE( INDEX(Product_Master!$I:$I, MATCH( INDEX(Pack_Master!$B:$B, MATCH($D13, Pack_Master!$A:$A, 0)), Product_Master!$B:$B, 0) )) * VALUE( INDEX(Pack_Master!$C:$C, MATCH($D13, Pack_Master!$A:$A, 0)) ) + VALUE( INDEX(Pack_Master!$D:$D, MATCH($D13, Pack_Master!$A:$A, 0)) ), "")} -> 109 | G13: {=IFERROR( ( INDEX(Pack_Master!E:E, MATCH($D13, Pack_Master!A:A, 0)) * INDEX(Pack_Master!F:F, MATCH($D13, Pack_Master!A:A, 0)) * INDEX(Pack_Master!G:G, MATCH($D13, Pack_Master!A:A, 0)) ) / INDEX(Config!C:C, MATCH($A13, Config!A:A, 0)), "")} -> 0.375 | H13: {=MAX( INDEX(Pack_Master!H:H, MATCH($D13, Pack_Master!A:A, 0)), IFERROR(G13, 0) )} -> 0.5 | I13: =IFERROR(__xludf.DUMMYFUNCTION("IFERROR( INDEX( FILTER(Shipping_Rate_Card!B:F, Shipping_Rate_Card!A:A=$A13), MATCH($H13, FILTER(Shipping_Rate_Card!B:B, Shipping_Rate_Card!A:A=$A13), 1), IF( INDEX(Config!B:B, MATCH($A13, Config!A:A, 0))=""Local"", 2, IF( INDEX(Config!B:B, "&"MATCH($A13, Config!A:A, 0))=""Regional"", 3, 4 ) ) ), """") "),67.0) -> 67 | J13: =IFERROR(__xludf.DUMMYFUNCTION("IFERROR( ( E13 * INDEX(FILTER(Pricing_Rules!E:E, Pricing_Rules!A:A=A13, Pricing_Rules!B:B=B13, Pricing_Rules!C:C<=E13, Pricing_Rules!D:D>=E13), 1) + INDEX(FILTER(Pricing_Rules!F:F, Pricing_Rules!A:A=A13, Pricing_Rules!B:B=B13, Pricing_Rules!C:C<=E13, "&"Pricing_Rules!D:D>=E13), 1) ) * (1 + IFERROR( INDEX(Config!D:D, MATCH(A13, Config!A:A, 0)), 0 )), """") "),5.8999999999999995) -> 5.9 | K13: =IFERROR(E13 - F13 - I13 - J13, "") -> 117.1 | L13: =IFERROR(K13 / E13, "") -> 0.3916388
A14: Amazon | B14: {=IF(D14="","", INDEX(Product_Master!A:A, MATCH( INDEX(Pack_Master!B:B, MATCH(D14, Pack_Master!A:A, 0)), Product_Master!B:B, 0 ) ))} -> Apparel_Caps_Beanies | C14: BEANIE-FOLD-BINGO-GREY | D14: BEANIE-FOLD-BINGO-GREY | E14: 299 | F14: {=IFERROR( VALUE( INDEX(Product_Master!$I:$I, MATCH( INDEX(Pack_Master!$B:$B, MATCH($D14, Pack_Master!$A:$A, 0)), Product_Master!$B:$B, 0) )) * VALUE( INDEX(Pack_Master!$C:$C, MATCH($D14, Pack_Master!$A:$A, 0)) ) + VALUE( INDEX(Pack_Master!$D:$D, MATCH($D14, Pack_Master!$A:$A, 0)) ), "")} -> 109 | G14: {=IFERROR( ( INDEX(Pack_Master!E:E, MATCH($D14, Pack_Master!A:A, 0)) * INDEX(Pack_Master!F:F, MATCH($D14, Pack_Master!A:A, 0)) * INDEX(Pack_Master!G:G, MATCH($D14, Pack_Master!A:A, 0)) ) / INDEX(Config!C:C, MATCH($A14, Config!A:A, 0)), "")} -> 0.375 | H14: {=MAX( INDEX(Pack_Master!H:H, MATCH($D14, Pack_Master!A:A, 0)), IFERROR(G14, 0) )} -> 0.5 | I14: =IFERROR(__xludf.DUMMYFUNCTION("IFERROR( INDEX( FILTER(Shipping_Rate_Card!B:F, Shipping_Rate_Card!A:A=$A14), MATCH($H14, FILTER(Shipping_Rate_Card!B:B, Shipping_Rate_Card!A:A=$A14), 1), IF( INDEX(Config!B:B, MATCH($A14, Config!A:A, 0))=""Local"", 2, IF( INDEX(Config!B:B, "&"MATCH($A14, Config!A:A, 0))=""Regional"", 3, 4 ) ) ), """") "),67.0) -> 67 | J14: =IFERROR(__xludf.DUMMYFUNCTION("IFERROR( ( E14 * INDEX(FILTER(Pricing_Rules!E:E, Pricing_Rules!A:A=A14, Pricing_Rules!B:B=B14, Pricing_Rules!C:C<=E14, Pricing_Rules!D:D>=E14), 1) + INDEX(FILTER(Pricing_Rules!F:F, Pricing_Rules!A:A=A14, Pricing_Rules!B:B=B14, Pricing_Rules!C:C<=E14, "&"Pricing_Rules!D:D>=E14), 1) ) * (1 + IFERROR( INDEX(Config!D:D, MATCH(A14, Config!A:A, 0)), 0 )), """") "),5.8999999999999995) -> 5.9 | K14: =IFERROR(E14 - F14 - I14 - J14, "") -> 117.1 | L14: =IFERROR(K14 / E14, "") -> 0.3916388
A15: Amazon | B15: {=IF(D15="","", INDEX(Product_Master!A:A, MATCH( INDEX(Pack_Master!B:B, MATCH(D15, Pack_Master!A:A, 0)), Product_Master!B:B, 0 ) ))} -> Apparel_Caps_Beanies | C15: BEANIE-FOLD-BINGO-LIGHTBROWN | D15: BEANIE-FOLD-BINGO-LIGHTBROWN | E15: 299 | F15: {=IFERROR( VALUE( INDEX(Product_Master!$I:$I, MATCH( INDEX(Pack_Master!$B:$B, MATCH($D15, Pack_Master!$A:$A, 0)), Product_Master!$B:$B, 0) )) * VALUE( INDEX(Pack_Master!$C:$C, MATCH($D15, Pack_Master!$A:$A, 0)) ) + VALUE( INDEX(Pack_Master!$D:$D, MATCH($D15, Pack_Master!$A:$A, 0)) ), "")} -> 109 | G15: {=IFERROR( ( INDEX(Pack_Master!E:E, MATCH($D15, Pack_Master!A:A, 0)) * INDEX(Pack_Master!F:F, MATCH($D15, Pack_Master!A:A, 0)) * INDEX(Pack_Master!G:G, MATCH($D15, Pack_Master!A:A, 0)) ) / INDEX(Config!C:C, MATCH($A15, Config!A:A, 0)), "")} -> 0.375 | H15: {=MAX( INDEX(Pack_Master!H:H, MATCH($D15, Pack_Master!A:A, 0)), IFERROR(G15, 0) )} -> 0.5 | I15: =IFERROR(__xludf.DUMMYFUNCTION("IFERROR( INDEX( FILTER(Shipping_Rate_Card!B:F, Shipping_Rate_Card!A:A=$A15), MATCH($H15, FILTER(Shipping_Rate_Card!B:B, Shipping_Rate_Card!A:A=$A15), 1), IF( INDEX(Config!B:B, MATCH($A15, Config!A:A, 0))=""Local"", 2, IF( INDEX(Config!B:B, "&"MATCH($A15, Config!A:A, 0))=""Regional"", 3, 4 ) ) ), """") "),67.0) -> 67 | J15: =IFERROR(__xludf.DUMMYFUNCTION("IFERROR( ( E15 * INDEX(FILTER(Pricing_Rules!E:E, Pricing_Rules!A:A=A15, Pricing_Rules!B:B=B15, Pricing_Rules!C:C<=E15, Pricing_Rules!D:D>=E15), 1) + INDEX(FILTER(Pricing_Rules!F:F, Pricing_Rules!A:A=A15, Pricing_Rules!B:B=B15, Pricing_Rules!C:C<=E15, "&"Pricing_Rules!D:D>=E15), 1) ) * (1 + IFERROR( INDEX(Config!D:D, MATCH(A15, Config!A:A, 0)), 0 )), """") "),5.8999999999999995) -> 5.9 | K15: =IFERROR(E15 - F15 - I15 - J15, "") -> 117.1 | L15: =IFERROR(K15 / E15, "") -> 0.3916388
A16: Amazon | B16: {=IF(D16="","", INDEX(Product_Master!A:A, MATCH( INDEX(Pack_Master!B:B, MATCH(D16, Pack_Master!A:A, 0)), Product_Master!B:B, 0 ) ))} -> Apparel_Caps_Beanies | C16: BEANIE-FOLD-CHECK-BLUE | D16: BEANIE-FOLD-CHECK-BLUE | E16: 299 | F16: {=IFERROR( VALUE( INDEX(Product_Master!$I:$I, MATCH( INDEX(Pack_Master!$B:$B, MATCH($D16, Pack_Master!$A:$A, 0)), Product_Master!$B:$B, 0) )) * VALUE( INDEX(Pack_Master!$C:$C, MATCH($D16, Pack_Master!$A:$A, 0)) ) + VALUE( INDEX(Pack_Master!$D:$D, MATCH($D16, Pack_Master!$A:$A, 0)) ), "")} -> 109 | G16: {=IFERROR( ( INDEX(Pack_Master!E:E, MATCH($D16, Pack_Master!A:A, 0)) * INDEX(Pack_Master!F:F, MATCH($D16, Pack_Master!A:A, 0)) * INDEX(Pack_Master!G:G, MATCH($D16, Pack_Master!A:A, 0)) ) / INDEX(Config!C:C, MATCH($A16, Config!A:A, 0)), "")} -> 0.375 | H16: {=MAX( INDEX(Pack_Master!H:H, MATCH($D16, Pack_Master!A:A, 0)), IFERROR(G16, 0) )} -> 0.5 | I16: =IFERROR(__xludf.DUMMYFUNCTION("IFERROR( INDEX( FILTER(Shipping_Rate_Card!B:F, Shipping_Rate_Card!A:A=$A16), MATCH($H16, FILTER(Shipping_Rate_Card!B:B, Shipping_Rate_Card!A:A=$A16), 1), IF( INDEX(Config!B:B, MATCH($A16, Config!A:A, 0))=""Local"", 2, IF( INDEX(Config!B:B, "&"MATCH($A16, Config!A:A, 0))=""Regional"", 3, 4 ) ) ), """") "),67.0) -> 67 | J16: =IFERROR(__xludf.DUMMYFUNCTION("IFERROR( ( E16 * INDEX(FILTER(Pricing_Rules!E:E, Pricing_Rules!A:A=A16, Pricing_Rules!B:B=B16, Pricing_Rules!C:C<=E16, Pricing_Rules!D:D>=E16), 1) + INDEX(FILTER(Pricing_Rules!F:F, Pricing_Rules!A:A=A16, Pricing_Rules!B:B=B16, Pricing_Rules!C:C<=E16, "&"Pricing_Rules!D:D>=E16), 1) ) * (1 + IFERROR( INDEX(Config!D:D, MATCH(A16, Config!A:A, 0)), 0 )), """") "),5.8999999999999995) -> 5.9 | K16: =IFERROR(E16 - F16 - I16 - J16, "") -> 117.1 | L16: =IFERROR(K16 / E16, "") -> 0.3916388
A17: Amazon | B17: {=IF(D17="","", INDEX(Product_Master!A:A, MATCH( INDEX(Pack_Master!B:B, MATCH(D17, Pack_Master!A:A, 0)), Product_Master!B:B, 0 ) ))} -> Apparel_Caps_Beanies | C17: BEANIE-FOLD-CHECK-GREY | D17: BEANIE-FOLD-CHECK-GREY | E17: 299 | F17: {=IFERROR( VALUE( INDEX(Product_Master!$I:$I, MATCH( INDEX(Pack_Master!$B:$B, MATCH($D17, Pack_Master!$A:$A, 0)), Product_Master!$B:$B, 0) )) * VALUE( INDEX(Pack_Master!$C:$C, MATCH($D17, Pack_Master!$A:$A, 0)) ) + VALUE( INDEX(Pack_Master!$D:$D, MATCH($D17, Pack_Master!$A:$A, 0)) ), "")} -> 109 | G17: {=IFERROR( ( INDEX(Pack_Master!E:E, MATCH($D17, Pack_Master!A:A, 0)) * INDEX(Pack_Master!F:F, MATCH($D17, Pack_Master!A:A, 0)) * INDEX(Pack_Master!G:G, MATCH($D17, Pack_Master!A:A, 0)) ) / INDEX(Config!C:C, MATCH($A17, Config!A:A, 0)), "")} -> 0.375 | H17: {=MAX( INDEX(Pack_Master!H:H, MATCH($D17, Pack_Master!A:A, 0)), IFERROR(G17, 0) )} -> 0.5 | I17: =IFERROR(__xludf.DUMMYFUNCTION("IFERROR( INDEX( FILTER(Shipping_Rate_Card!B:F, Shipping_Rate_Card!A:A=$A17), MATCH($H17, FILTER(Shipping_Rate_Card!B:B, Shipping_Rate_Card!A:A=$A17), 1), IF( INDEX(Config!B:B, MATCH($A17, Config!A:A, 0))=""Local"", 2, IF( INDEX(Config!B:B, "&"MATCH($A17, Config!A:A, 0))=""Regional"", 3, 4 ) ) ), """") "),67.0) -> 67 | J17: =IFERROR(__xludf.DUMMYFUNCTION("IFERROR( ( E17 * INDEX(FILTER(Pricing_Rules!E:E, Pricing_Rules!A:A=A17, Pricing_Rules!B:B=B17, Pricing_Rules!C:C<=E17, Pricing_Rules!D:D>=E17), 1) + INDEX(FILTER(Pricing_Rules!F:F, Pricing_Rules!A:A=A17, Pricing_Rules!B:B=B17, Pricing_Rules!C:C<=E17, "&"Pricing_Rules!D:D>=E17), 1) ) * (1 + IFERROR( INDEX(Config!D:D, MATCH(A17, Config!A:A, 0)), 0 )), """") "),5.8999999999999995) -> 5.9 | K17: =IFERROR(E17 - F17 - I17 - J17, "") -> 117.1 | L17: =IFERROR(K17 / E17, "") -> 0.3916388
A18: Amazon | B18: {=IF(D18="","", INDEX(Product_Master!A:A, MATCH( INDEX(Pack_Master!B:B, MATCH(D18, Pack_Master!A:A, 0)), Product_Master!B:B, 0 ) ))} -> Apparel_Caps_Beanies | C18: BEANIE-FOLD-CHECK-LIGHTBROWN | D18: BEANIE-FOLD-CHECK-LIGHTBROWN | E18: 299 | F18: {=IFERROR( VALUE( INDEX(Product_Master!$I:$I, MATCH( INDEX(Pack_Master!$B:$B, MATCH($D18, Pack_Master!$A:$A, 0)), Product_Master!$B:$B, 0) )) * VALUE( INDEX(Pack_Master!$C:$C, MATCH($D18, Pack_Master!$A:$A, 0)) ) + VALUE( INDEX(Pack_Master!$D:$D, MATCH($D18, Pack_Master!$A:$A, 0)) ), "")} -> 109 | G18: {=IFERROR( ( INDEX(Pack_Master!E:E, MATCH($D18, Pack_Master!A:A, 0)) * INDEX(Pack_Master!F:F, MATCH($D18, Pack_Master!A:A, 0)) * INDEX(Pack_Master!G:G, MATCH($D18, Pack_Master!A:A, 0)) ) / INDEX(Config!C:C, MATCH($A18, Config!A:A, 0)), "")} -> 0.375 | H18: {=MAX( INDEX(Pack_Master!H:H, MATCH($D18, Pack_Master!A:A, 0)), IFERROR(G18, 0) )} -> 0.5 | I18: =IFERROR(__xludf.DUMMYFUNCTION("IFERROR( INDEX( FILTER(Shipping_Rate_Card!B:F, Shipping_Rate_Card!A:A=$A18), MATCH($H18, FILTER(Shipping_Rate_Card!B:B, Shipping_Rate_Card!A:A=$A18), 1), IF( INDEX(Config!B:B, MATCH($A18, Config!A:A, 0))=""Local"", 2, IF( INDEX(Config!B:B, "&"MATCH($A18, Config!A:A, 0))=""Regional"", 3, 4 ) ) ), """") "),67.0) -> 67 | J18: =IFERROR(__xludf.DUMMYFUNCTION("IFERROR( ( E18 * INDEX(FILTER(Pricing_Rules!E:E, Pricing_Rules!A:A=A18, Pricing_Rules!B:B=B18, Pricing_Rules!C:C<=E18, Pricing_Rules!D:D>=E18), 1) + INDEX(FILTER(Pricing_Rules!F:F, Pricing_Rules!A:A=A18, Pricing_Rules!B:B=B18, Pricing_Rules!C:C<=E18, "&"Pricing_Rules!D:D>=E18), 1) ) * (1 + IFERROR( INDEX(Config!D:D, MATCH(A18, Config!A:A, 0)), 0 )), """") "),5.8999999999999995) -> 5.9 | K18: =IFERROR(E18 - F18 - I18 - J18, "") -> 117.1 | L18: =IFERROR(K18 / E18, "") -> 0.3916388
A19: Amazon | B19: {=IF(D19="","", INDEX(Product_Master!A:A, MATCH( INDEX(Pack_Master!B:B, MATCH(D19, Pack_Master!A:A, 0)), Product_Master!B:B, 0 ) ))} -> Apparel_Caps_Beanies | C19: BEANIE-FOLD-CHECK-MAROON | D19: BEANIE-FOLD-CHECK-MAROON | E19: 299 | F19: {=IFERROR( VALUE( INDEX(Product_Master!$I:$I, MATCH( INDEX(Pack_Master!$B:$B, MATCH($D19, Pack_Master!$A:$A, 0)), Product_Master!$B:$B, 0) )) * VALUE( INDEX(Pack_Master!$C:$C, MATCH($D19, Pack_Master!$A:$A, 0)) ) + VALUE( INDEX(Pack_Master!$D:$D, MATCH($D19, Pack_Master!$A:$A, 0)) ), "")} -> 109 | G19: {=IFERROR( ( INDEX(Pack_Master!E:E, MATCH($D19, Pack_Master!A:A, 0)) * INDEX(Pack_Master!F:F, MATCH($D19, Pack_Master!A:A, 0)) * INDEX(Pack_Master!G:G, MATCH($D19, Pack_Master!A:A, 0)) ) / INDEX(Config!C:C, MATCH($A19, Config!A:A, 0)), "")} -> 0.375 | H19: {=MAX( INDEX(Pack_Master!H:H, MATCH($D19, Pack_Master!A:A, 0)), IFERROR(G19, 0) )} -> 0.5 | I19: =IFERROR(__xludf.DUMMYFUNCTION("IFERROR( INDEX( FILTER(Shipping_Rate_Card!B:F, Shipping_Rate_Card!A:A=$A19), MATCH($H19, FILTER(Shipping_Rate_Card!B:B, Shipping_Rate_Card!A:A=$A19), 1), IF( INDEX(Config!B:B, MATCH($A19, Config!A:A, 0))=""Local"", 2, IF( INDEX(Config!B:B, "&"MATCH($A19, Config!A:A, 0))=""Regional"", 3, 4 ) ) ), """") "),67.0) -> 67 | J19: =IFERROR(__xludf.DUMMYFUNCTION("IFERROR( ( E19 * INDEX(FILTER(Pricing_Rules!E:E, Pricing_Rules!A:A=A19, Pricing_Rules!B:B=B19, Pricing_Rules!C:C<=E19, Pricing_Rules!D:D>=E19), 1) + INDEX(FILTER(Pricing_Rules!F:F, Pricing_Rules!A:A=A19, Pricing_Rules!B:B=B19, Pricing_Rules!C:C<=E19, "&"Pricing_Rules!D:D>=E19), 1) ) * (1 + IFERROR( INDEX(Config!D:D, MATCH(A19, Config!A:A, 0)), 0 )), """") "),5.8999999999999995) -> 5.9 | K19: =IFERROR(E19 - F19 - I19 - J19, "") -> 117.1 | L19: =IFERROR(K19 / E19, "") -> 0.3916388
A20: Amazon | B20: {=IF(D20="","", INDEX(Product_Master!A:A, MATCH( INDEX(Pack_Master!B:B, MATCH(D20, Pack_Master!A:A, 0)), Product_Master!B:B, 0 ) ))} -> Apparel_Caps_Beanies | C20: BEANIE-FOLD-CHECK-OLIVE | D20: BEANIE-FOLD-CHECK-OLIVE | E20: 299 | F20: {=IFERROR( VALUE( INDEX(Product_Master!$I:$I, MATCH( INDEX(Pack_Master!$B:$B, MATCH($D20, Pack_Master!$A:$A, 0)), Product_Master!$B:$B, 0) )) * VALUE( INDEX(Pack_Master!$C:$C, MATCH($D20, Pack_Master!$A:$A, 0)) ) + VALUE( INDEX(Pack_Master!$D:$D, MATCH($D20, Pack_Master!$A:$A, 0)) ), "")} -> 109 | G20: {=IFERROR( ( INDEX(Pack_Master!E:E, MATCH($D20, Pack_Master!A:A, 0)) * INDEX(Pack_Master!F:F, MATCH($D20, Pack_Master!A:A, 0)) * INDEX(Pack_Master!G:G, MATCH($D20, Pack_Master!A:A, 0)) ) / INDEX(Config!C:C, MATCH($A20, Config!A:A, 0)), "")} -> 0.375 | H20: {=MAX( INDEX(Pack_Master!H:H, MATCH($D20, Pack_Master!A:A, 0)), IFERROR(G20, 0) )} -> 0.5 | I20: =IFERROR(__xludf.DUMMYFUNCTION("IFERROR( INDEX( FILTER(Shipping_Rate_Card!B:F, Shipping_Rate_Card!A:A=$A20), MATCH($H20, FILTER(Shipping_Rate_Card!B:B, Shipping_Rate_Card!A:A=$A20), 1), IF( INDEX(Config!B:B, MATCH($A20, Config!A:A, 0))=""Local"", 2, IF( INDEX(Config!B:B, "&"MATCH($A20, Config!A:A, 0))=""Regional"", 3, 4 ) ) ), """") "),67.0) -> 67 | J20: =IFERROR(__xludf.DUMMYFUNCTION("IFERROR( ( E20 * INDEX(FILTER(Pricing_Rules!E:E, Pricing_Rules!A:A=A20, Pricing_Rules!B:B=B20, Pricing_Rules!C:C<=E20, Pricing_Rules!D:D>=E20), 1) + INDEX(FILTER(Pricing_Rules!F:F, Pricing_Rules!A:A=A20, Pricing_Rules!B:B=B20, Pricing_Rules!C:C<=E20, "&"Pricing_Rules!D:D>=E20), 1) ) * (1 + IFERROR( INDEX(Config!D:D, MATCH(A20, Config!A:A, 0)), 0 )), """") "),5.8999999999999995) -> 5.9 | K20: =IFERROR(E20 - F20 - I20 - J20, "") -> 117.1 | L20: =IFERROR(K20 / E20, "") -> 0.3916388
A21: Amazon | B21: {=IF(D21="","", INDEX(Product_Master!A:A, MATCH( INDEX(Pack_Master!B:B, MATCH(D21, Pack_Master!A:A, 0)), Product_Master!B:B, 0 ) ))} -> Apparel_Caps_Beanies | C21: BEANIE-FOLD-KING-BLUE | D21: BEANIE-FOLD-KING-BLUE | E21: 299 | F21: {=IFERROR( VALUE( INDEX(Product_Master!$I:$I, MATCH( INDEX(Pack_Master!$B:$B, MATCH($D21, Pack_Master!$A:$A, 0)), Product_Master!$B:$B, 0) )) * VALUE( INDEX(Pack_Master!$C:$C, MATCH($D21, Pack_Master!$A:$A, 0)) ) + VALUE( INDEX(Pack_Master!$D:$D, MATCH($D21, Pack_Master!$A:$A, 0)) ), "")} -> 109 | G21: {=IFERROR( ( INDEX(Pack_Master!E:E, MATCH($D21, Pack_Master!A:A, 0)) * INDEX(Pack_Master!F:F, MATCH($D21, Pack_Master!A:A, 0)) * INDEX(Pack_Master!G:G, MATCH($D21, Pack_Master!A:A, 0)) ) / INDEX(Config!C:C, MATCH($A21, Config!A:A, 0)), "")} -> 0.375 | H21: {=MAX( INDEX(Pack_Master!H:H, MATCH($D21, Pack_Master!A:A, 0)), IFERROR(G21, 0) )} -> 0.5 | I21: =IFERROR(__xludf.DUMMYFUNCTION("IFERROR( INDEX( FILTER(Shipping_Rate_Card!B:F, Shipping_Rate_Card!A:A=$A21), MATCH($H21, FILTER(Shipping_Rate_Card!B:B, Shipping_Rate_Card!A:A=$A21), 1), IF( INDEX(Config!B:B, MATCH($A21, Config!A:A, 0))=""Local"", 2, IF( INDEX(Config!B:B, "&"MATCH($A21, Config!A:A, 0))=""Regional"", 3, 4 ) ) ), """") "),67.0) -> 67 | J21: =IFERROR(__xludf.DUMMYFUNCTION("IFERROR( ( E21 * INDEX(FILTER(Pricing_Rules!E:E, Pricing_Rules!A:A=A21, Pricing_Rules!B:B=B21, Pricing_Rules!C:C<=E21, Pricing_Rules!D:D>=E21), 1) + INDEX(FILTER(Pricing_Rules!F:F, Pricing_Rules!A:A=A21, Pricing_Rules!B:B=B21, Pricing_Rules!C:C<=E21, "&"Pricing_Rules!D:D>=E21), 1) ) * (1 + IFERROR( INDEX(Config!D:D, MATCH(A21, Config!A:A, 0)), 0 )), """") "),5.8999999999999995) -> 5.9 | K21: =IFERROR(E21 - F21 - I21 - J21, "") -> 117.1 | L21: =IFERROR(K21 / E21, "") -> 0.3916388
A22: Amazon | B22: {=IF(D22="","", INDEX(Product_Master!A:A, MATCH( INDEX(Pack_Master!B:B, MATCH(D22, Pack_Master!A:A, 0)), Product_Master!B:B, 0 ) ))} -> Apparel_Caps_Beanies | C22: BEANIE-FOLD-KING-BROWN | D22: BEANIE-FOLD-KING-BROWN | E22: 299 | F22: {=IFERROR( VALUE( INDEX(Product_Master!$I:$I, MATCH( INDEX(Pack_Master!$B:$B, MATCH($D22, Pack_Master!$A:$A, 0)), Product_Master!$B:$B, 0) )) * VALUE( INDEX(Pack_Master!$C:$C, MATCH($D22, Pack_Master!$A:$A, 0)) ) + VALUE( INDEX(Pack_Master!$D:$D, MATCH($D22, Pack_Master!$A:$A, 0)) ), "")} -> 109 | G22: {=IFERROR( ( INDEX(Pack_Master!E:E, MATCH($D22, Pack_Master!A:A, 0)) * INDEX(Pack_Master!F:F, MATCH($D22, Pack_Master!A:A, 0)) * INDEX(Pack_Master!G:G, MATCH($D22, Pack_Master!A:A, 0)) ) / INDEX(Config!C:C, MATCH($A22, Config!A:A, 0)), "")} -> 0.375 | H22: {=MAX( INDEX(Pack_Master!H:H, MATCH($D22, Pack_Master!A:A, 0)), IFERROR(G22, 0) )} -> 0.5 | I22: =IFERROR(__xludf.DUMMYFUNCTION("IFERROR( INDEX( FILTER(Shipping_Rate_Card!B:F, Shipping_Rate_Card!A:A=$A22), MATCH($H22, FILTER(Shipping_Rate_Card!B:B, Shipping_Rate_Card!A:A=$A22), 1), IF( INDEX(Config!B:B, MATCH($A22, Config!A:A, 0))=""Local"", 2, IF( INDEX(Config!B:B, "&"MATCH($A22, Config!A:A, 0))=""Regional"", 3, 4 ) ) ), """") "),67.0) -> 67 | J22: =IFERROR(__xludf.DUMMYFUNCTION("IFERROR( ( E22 * INDEX(FILTER(Pricing_Rules!E:E, Pricing_Rules!A:A=A22, Pricing_Rules!B:B=B22, Pricing_Rules!C:C<=E22, Pricing_Rules!D:D>=E22), 1) + INDEX(FILTER(Pricing_Rules!F:F, Pricing_Rules!A:A=A22, Pricing_Rules!B:B=B22, Pricing_Rules!C:C<=E22, "&"Pricing_Rules!D:D>=E22), 1) ) * (1 + IFERROR( INDEX(Config!D:D, MATCH(A22, Config!A:A, 0)), 0 )), """") "),5.8999999999999995) -> 5.9 | K22: =IFERROR(E22 - F22 - I22 - J22, "") -> 117.1 | L22: =IFERROR(K22 / E22, "") -> 0.3916388
A23: Amazon | B23: {=IF(D23="","", INDEX(Product_Master!A:A, MATCH( INDEX(Pack_Master!B:B, MATCH(D23, Pack_Master!A:A, 0)), Product_Master!B:B, 0 ) ))} -> Apparel_Caps_Beanies | C23: BEANIE-FOLD-KING-GREEN | D23: BEANIE-FOLD-KING-GREEN | E23: 299 | F23: {=IFERROR( VALUE( INDEX(Product_Master!$I:$I, MATCH( INDEX(Pack_Master!$B:$B, MATCH($D23, Pack_Master!$A:$A, 0)), Product_Master!$B:$B, 0) )) * VALUE( INDEX(Pack_Master!$C:$C, MATCH($D23, Pack_Master!$A:$A, 0)) ) + VALUE( INDEX(Pack_Master!$D:$D, MATCH($D23, Pack_Master!$A:$A, 0)) ), "")} -> 109 | G23: {=IFERROR( ( INDEX(Pack_Master!E:E, MATCH($D23, Pack_Master!A:A, 0)) * INDEX(Pack_Master!F:F, MATCH($D23, Pack_Master!A:A, 0)) * INDEX(Pack_Master!G:G, MATCH($D23, Pack_Master!A:A, 0)) ) / INDEX(Config!C:C, MATCH($A23, Config!A:A, 0)), "")} -> 0.375 | H23: {=MAX( INDEX(Pack_Master!H:H, MATCH($D23, Pack_Master!A:A, 0)), IFERROR(G23, 0) )} -> 0.5 | I23: =IFERROR(__xludf.DUMMYFUNCTION("IFERROR( INDEX( FILTER(Shipping_Rate_Card!B:F, Shipping_Rate_Card!A:A=$A23), MATCH($H23, FILTER(Shipping_Rate_Card!B:B, Shipping_Rate_Card!A:A=$A23), 1), IF( INDEX(Config!B:B, MATCH($A23, Config!A:A, 0))=""Local"", 2, IF( INDEX(Config!B:B, "&"MATCH($A23, Config!A:A, 0))=""Regional"", 3, 4 ) ) ), """") "),67.0) -> 67 | J23: =IFERROR(__xludf.DUMMYFUNCTION("IFERROR( ( E23 * INDEX(FILTER(Pricing_Rules!E:E, Pricing_Rules!A:A=A23, Pricing_Rules!B:B=B23, Pricing_Rules!C:C<=E23, Pricing_Rules!D:D>=E23), 1) + INDEX(FILTER(Pricing_Rules!F:F, Pricing_Rules!A:A=A23, Pricing_Rules!B:B=B23, Pricing_Rules!C:C<=E23, "&"Pricing_Rules!D:D>=E23), 1) ) * (1 + IFERROR( INDEX(Config!D:D, MATCH(A23, Config!A:A, 0)), 0 )), """") "),5.8999999999999995) -> 5.9 | K23: =IFERROR(E23 - F23 - I23 - J23, "") -> 117.1 | L23: =IFERROR(K23 / E23, "") -> 0.3916388
